<?xml version="1.0" ?>
<sdf version="1.5">
  <model name="multigo">  
  <pose>0.0 0.0 0.0 0.0 0.0 0.0</pose>

    <link name="base_footprint"/>

    <link name="base_link">

      <inertial>
          <pose>0.000602 0 0.476823 0 -0 0</pose>
          <mass>50.435</mass>
          <inertia>
            <ixx>3.02781</ixx>
            <ixy>0</ixy>
            <ixz>-0.012125</ixz>
            <iyy>3.43197</iyy>
            <iyz>0</iyz>
            <izz>0.968001</izz>
          </inertia>
        </inertial>

      <collision name="base_collision">
        <pose>0.15 0 0.002 -0.0 -0.0 1.57</pose>
        <geometry>
          <mesh>
            <uri>model://multigo/meshes/multigo.stl</uri>
            <scale>0.001 0.001 0.001</scale>
          </mesh>
        </geometry>
      </collision>

      <visual name="base_visual">
        <pose>0.15 0 0.002 -0.0 -0.0 1.57</pose>
          <geometry>
            <mesh>
              <uri>model://multigo/meshes/multigo.stl</uri>
              <scale>0.001 0.001 0.001</scale>
          </mesh>
          </geometry>
          <material>
            <ambient>0.8392 0.6314 0 1</ambient>
            <diffuse>0.8392 0.6314 0 1</diffuse>
            <specular>0.99 0.99 0.99 1</specular>
            <emissive>0 0 0 0</emissive>
          </material>
        </visual>
    </link>

    <link name="imu_link">
      <sensor name="tb3_imu" type="imu">
        <always_on>true</always_on>
        <update_rate>200</update_rate>
        <imu>
          <angular_velocity>
            <x>
              <noise type="gaussian">
                <mean>0.0</mean>
                <stddev>2e-4</stddev>
              </noise>
            </x>
            <y>
              <noise type="gaussian">
                <mean>0.0</mean>
                <stddev>2e-4</stddev>
              </noise>
            </y>
            <z>
              <noise type="gaussian">
                <mean>0.0</mean>
                <stddev>2e-4</stddev>
              </noise>
            </z>
          </angular_velocity>
          <linear_acceleration>
            <x>
              <noise type="gaussian">
                <mean>0.0</mean>
                <stddev>1.7e-2</stddev>
              </noise>
            </x>
            <y>
              <noise type="gaussian">
                <mean>0.0</mean>
                <stddev>1.7e-2</stddev>
              </noise>
            </y>
            <z>
              <noise type="gaussian">
                <mean>0.0</mean>
                <stddev>1.7e-2</stddev>
              </noise>
            </z>
          </linear_acceleration>
        </imu>
        <plugin name='imu_plugin' filename='libgazebo_ros_imu_sensor.so'>
          <ros>
            <!-- <namespace>multigo</namespace> -->
            <remapping>~/out:=imu</remapping>
          </ros>
        </plugin>
      </sensor>
    </link>

    <link name="base_scan">    
      <inertial>
        <pose relative_to="lidar_joint">0 0 0 0 -0 0</pose>
        <inertia>
          <ixx>0.001</ixx>
          <ixy>0.000</ixy>
          <ixz>0.000</ixz>
          <iyy>0.001</iyy>
          <iyz>0.000</iyz>
          <izz>0.001</izz>
        </inertia>
        <mass>0.114</mass>
      </inertial>

      <collision name="lidar_sensor_collision">
        <!-- <pose>0.21 0 0.9 0 -0 0</pose> -->
        <pose relative_to="lidar_joint">0 0 0 0 -0 0</pose>
        <geometry>
          <cylinder>
            <radius>0.0508</radius>
            <length>0.055</length>
          </cylinder>
        </geometry>
      </collision>

      <visual name="lidar_sensor_visual">
        <!-- <pose>0.21 0 0.9 0 -0 0</pose> -->
        <pose relative_to="lidar_joint">0 0 0 0 -0 0</pose>
        <geometry>
            <cylinder>
              <length>0.05</length>
              <radius>0.0375</radius>
            </cylinder>
          </geometry>
          <material>
            <ambient>0.003 0.639 0.223 1</ambient>
            <diffuse>0.003 0.639 0.223 1</diffuse>
            <specular>0.003 0.639 0.223 1</specular>
            <emissive>0 0 0 0</emissive>
          </material>
      </visual>

      <sensor name='lidar_3d' type='gpu_ray'>
        <always_on>true</always_on>
        <visualize>false</visualize>
        <!-- <pose>0.21 0 0.9 0 -0 0</pose> -->
        <pose relative_to="lidar_joint">0 0 0 0 -0 0</pose>
        <update_rate>10</update_rate>
            <ray>
                <scan>
                    <horizontal>
                        <samples>360</samples>
                        <resolution>1</resolution>
                        <min_angle>-3.1416</min_angle>
                        <max_angle>3.1416</max_angle>
                    </horizontal>
                    <vertical>
                        <samples>16</samples> <!-- Increase vertical samples for 3D scan -->
                        <resolution>1</resolution>
                        <min_angle>-0.4</min_angle> <!-- Adjust vertical min angle -->
                        <max_angle>0.0</max_angle>  <!-- Adjust vertical max angle -->
                    </vertical>
                </scan>
                <range>
                    <min>0.2</min>
                    <max>20</max> <!-- Increase max range for 3D lidar -->
                    <resolution>0.01</resolution>
                </range>
            </ray>

        <!-- <plugin name='lidar_2d_controller' filename='libgazebo_ros_ray_sensor.so'>
          <ros>
            <remapping>~/out:=scan_laserscan</remapping>
          </ros>
          <output_type>sensor_msgs/LaserScan</output_type>
          <frame_name>base_scan</frame_name>
        </plugin> -->

              <!-- Additional plugin for LaserScan output -->
      <plugin name='lidar_3d_controller' filename='libgazebo_ros_ray_sensor.so'>
          <ros>
              <remapping>~/out:=scan_pointcloud</remapping>
          </ros>
          <output_type>sensor_msgs/PointCloud2</output_type>
                <alwaysOn>1</alwaysOn>
                <updateRate>10</updateRate>
                <frame_name>base_scan</frame_name>
      </plugin>

        <pose>0 0 1.1 0 -0 0</pose>
      </sensor>
    </link>

    <link name="camera_link"/>

    <!-- front Left camera -->
    <link name="camera_front_left_frame">
      <inertial>
        <inertia>
          <ixx>0.001</ixx>
          <ixy>0.000</ixy>
          <ixz>0.000</ixz>
          <iyy>0.001</iyy>
          <iyz>0.000</iyz>
          <izz>0.001</izz>
        </inertia>
        <mass>0.035</mass>
      </inertial>

      <pose relative_to="camera_front_left_joint">0.000 0.00 0.00 0 0 0</pose>
      <sensor name="camera" type="camera">
        <always_on>true</always_on>
        <visualize>true</visualize>
        <update_rate>10</update_rate>
        <camera name="intel_realsense_r200_front">
          <horizontal_fov>1.1519</horizontal_fov>
          <image>
            <width>1280</width>
            <height>720</height>
            <format>L8</format> <!-- grayscale -->
          </image>
          <clip>
            <near>0.02</near>
            <far>300</far>
          </clip>
          <noise>
            <type>gaussian</type>
            <mean>0.0</mean>
            <stddev>0.007</stddev>
          </noise>
        </camera>
          <plugin name="camera_driver_front" filename="libgazebo_ros_camera.so">
          <frameName>camera_front_left_frame</frameName>
            <ros>
              <remapping>/camera/camera_info:=/camera_left/color/camera_info</remapping>
              <remapping>/camera/image_raw:=/camera_left/color/image_raw</remapping>
 
              <qos>
                <topic name='/camera_left/color/image_raw'>
                  <publisher>
                    <reliability>reliable</reliability>
                  </publisher>
                </topic>
              </qos>
            </ros>
          </plugin>
      </sensor>
    </link>   

  
    <!-- Front Right Camera - Standard Raspberry Pi Camera -->
    <link name="camera_front_right_frame">
      <inertial>
        <inertia>
          <ixx>0.001</ixx>
          <ixy>0.000</ixy>
          <ixz>0.000</ixz>
          <iyy>0.001</iyy>
          <iyz>0.000</iyz>
          <izz>0.001</izz>
        </inertia>
        <mass>0.035</mass>
      </inertial>

      <pose relative_to="camera_front_right_joint">0.000 0.00 0.00 0 0 0</pose>
      <sensor name="camera" type="camera">
        <always_on>true</always_on>
        <visualize>true</visualize>
        <update_rate>10</update_rate>
        <camera name="raspberry_pi_right">
          <horizontal_fov>1.1519</horizontal_fov>
          <image>
            <width>1280</width>
            <height>720</height>
            <format>L8</format> <!-- grayscale -->
          </image>
          <clip>
            <near>0.02</near>
            <far>300</far>
          </clip>
          <noise>
            <type>gaussian</type>
            <mean>0.0</mean>
            <stddev>0.007</stddev>
          </noise>
        </camera>
          <plugin name="camera_driver_right" filename="libgazebo_ros_camera.so">
          <frameName>camera_front_right_frame</frameName>
            <ros>
              <remapping>/camera/camera_info:=/camera_right/color/camera_info</remapping>
              <remapping>/camera/image_raw:=/camera_right/color/image_raw</remapping>
              <qos>
                <topic name='/camera_right/color/image_raw'>
                  <publisher>
                    <reliability>reliable</reliability>
                  </publisher>
                </topic>
              </qos>
            </ros>
          </plugin>
      </sensor>
    </link>   
    

    <link name="tof_sensor_link_1">
      <inertial>
        <inertia>
          <ixx>0.001</ixx>
          <ixy>0.000</ixy>
          <ixz>0.000</ixz>
          <iyy>0.001</iyy>
          <iyz>0.000</iyz>
          <izz>0.001</izz>
        </inertia>
        <mass>0.035</mass>
      </inertial>
      <pose relative_to="camera_joint">-0.082 0.178 0.0 0 0 0</pose> 
      <sensor name="tof_sensor_1" type="ray">
          <always_on>true</always_on>
            <visualize>true</visualize>
        <ray>
          <scan>
            <horizontal>
              <samples>1</samples>
              <resolution>1</resolution>
              <min_angle>-0.0</min_angle> 
              <max_angle>0.0</max_angle>
            </horizontal>
          </scan>
          <range>
            <min>0.04</min>  
            <max>4.0</max>  
            <resolution>0.01</resolution> 
          </range>
        </ray>
        <plugin name="gazebo_ros_range_1" filename="libgazebo_ros_range.so">
          <ros>
            <namespace>multigo</namespace>
            <remapping>
              <remap from="~/out" to="tof_sensor_data"/>
            </remapping>
          </ros>
          <output_type>sensor_msgs/Range</output_type>
          <frame_name>tof_sensor_link_1</frame_name>
          <update_rate>50</update_rate>
        </plugin>
      </sensor>
    </link> 


    <link name="tof_sensor_link_2">
      <inertial>
        <inertia>
          <ixx>0.001</ixx>
          <ixy>0.000</ixy>
          <ixz>0.000</ixz>
          <iyy>0.001</iyy>
          <iyz>0.000</iyz>
          <izz>0.001</izz>
        </inertia>
        <mass>0.035</mass>
      </inertial>
      <pose relative_to="camera_joint">-0.082 -0.178 0.0 0 0 0</pose>
      <sensor name="tof_sensor_2" type="ray">
          <always_on>true</always_on>
            <visualize>true</visualize>
        <ray>
          <scan>
            <horizontal>
              <samples>1</samples> 
              <resolution>1</resolution>
              <min_angle>-0.0</min_angle> 
              <max_angle>0.0</max_angle> 
            </horizontal>
          </scan>
          <range>
            <min>0.04</min>  
            <max>4.0</max>   
            <resolution>0.01</resolution> 
          </range>
        </ray>
        <plugin name="gazebo_ros_range_2" filename="libgazebo_ros_range.so">
          <ros>
            <namespace>multigo</namespace>
            <remapping>
              <remap from="~/out" to="tof_sensor_data_2"/>
            </remapping>
          </ros>
          <output_type>sensor_msgs/Range</output_type>
          <frame_name>tof_sensor_link_2</frame_name>
          <update_rate>50</update_rate> 
        </plugin>
      </sensor>
    </link>  




    <!-- Joints  -->

    <joint name="camera_joint" type="fixed">
      <parent>base_link</parent>
      <child>camera_link</child>
      <pose>0.26 0.0 0.30 0 -0 0</pose>
      <axis>
        <xyz>0 0 1</xyz>
      </axis>
    </joint>

    <joint name="camera_front_left_joint" type="fixed">
      <parent>camera_link</parent>
      <child>camera_front_left_frame</child>
      <pose relative_to="camera_joint">-0.082 0.178 0.0 0 0 0</pose>
      <axis>
        <xyz>0 0 1</xyz>
      </axis>
    </joint>

    <joint name="camera_front_right_joint" type="fixed">
      <parent>camera_link</parent>
      <child>camera_front_right_frame</child>
      <pose relative_to="camera_joint">-0.082 -0.178 0.0 0 0 0</pose>
      <axis>
        <xyz>0 0 1</xyz>
      </axis>
    </joint>


    <joint name="tof_sensor_joint_1" type="fixed">
      <parent>camera_link</parent>
      <child>tof_sensor_link_1</child>
      <pose relative_to="camera_joint">0.000 0.1 0.00 0 0 0</pose>
      <axis>
        <xyz>0 0 1</xyz>
      </axis>
    </joint>

    <joint name="tof_sensor_joint_2" type="fixed">
      <parent>camera_link</parent>
      <child>tof_sensor_link_2</child>
      <pose relative_to="camera_joint">0.000 -0.32 0.00 0 0 0</pose>
      <axis>
        <xyz>0 0 1</xyz>
      </axis>
    </joint>

    


    <joint name="base_joint" type="fixed">
      <parent>base_footprint</parent>
      <child>base_link</child>
      <pose>0.0 0.0 0.010 0 0 0</pose>
    </joint>



    <joint name="imu_joint" type="fixed">
      <parent>base_link</parent>
      <child>imu_link</child>
      <pose>-0.032 0 0.068 0 0 0</pose>
      <axis>
        <xyz>0 0 1</xyz>
      </axis>
    </joint>    

    <joint name="lidar_joint" type="fixed">
      <parent>base_link</parent>
      <child>base_scan</child>
      <pose>0.21 0 0.5 0 -0 0</pose>
      <axis>
        <xyz>0 0 1</xyz>
      </axis>
    </joint>



<!-- Wheels -->
      <joint name='front_left_wheel_joint' type='revolute'>
        <pose relative_to='base_link'>0.15 0.183 0.076 0 -0 0</pose>
        <parent>base_link</parent>
        <child>front_left_wheel_link</child>
        <axis>
          <xyz>0 1 0</xyz>
          <limit>
            <lower>-1e+16</lower>
            <upper>1e+16</upper>
          </limit>
          <dynamics>
            <spring_reference>0</spring_reference>
            <spring_stiffness>0</spring_stiffness>
          </dynamics>
        </axis>
      </joint>
      <link name='front_left_wheel_link'>
        <pose relative_to='front_left_wheel_joint'>0 0 0 0 -0 0</pose>
        <inertial>
          <pose>0 0 0 0 -0 0</pose>
          <mass>2.6</mass>
          <inertia>
            <ixx>0.00138624</ixx>
            <ixy>0</ixy>
            <ixz>0</ixz>
            <iyy>0.00138624</iyy>
            <iyz>0</iyz>
            <izz>0.00138624</izz>
          </inertia>
        </inertial>
        <collision name='front_left_wheel_link_collision'>
          <pose>0 0 0 1.5708 -0 0</pose>
          <geometry>
            <cylinder>
              <length>0.056</length>
              <radius>0.076</radius>
            </cylinder>
          </geometry>
          <surface>
            <contact>
              <ode/>
            </contact>
            <friction>
              <ode>
                <mu>0.01</mu>
                <mu2>0.01</mu2>
              </ode>
              <torsional>
                <ode/>
              </torsional>
            </friction>
            <bounce/>
          </surface>
          <max_contacts>10</max_contacts>
        </collision>
        <visual name='front_left_wheel_link_visual'>
          <pose>0 0 0 1.5708 -0 0</pose>
          <geometry>
            <cylinder>
              <length>0.056</length>
              <radius>0.076</radius>
            </cylinder>
          </geometry>
          <material>
            <ambient>0.1764 0.4588 0.8509 1</ambient>
            <diffuse>0.1764 0.4588 0.8509 1</diffuse>
            <specular>0.1764 0.4588 0.8509 1</specular>
            <emissive>0 0 0 0</emissive>
          </material>
        </visual>
        <self_collide>0</self_collide>
        <enable_wind>0</enable_wind>
        <kinematic>0</kinematic>
      </link>
      <joint name='front_right_wheel_joint' type='revolute'>
        <pose relative_to='base_link'>0.15 -0.183 0.076 0 -0 0</pose>
        <parent>base_link</parent>
        <child>front_right_wheel_link</child>
        <axis>
          <xyz>0 1 0</xyz>
          <limit>
            <lower>-1e+16</lower>
            <upper>1e+16</upper>
          </limit>
          <dynamics>
            <spring_reference>0</spring_reference>
            <spring_stiffness>0</spring_stiffness>
          </dynamics>
        </axis>
      </joint>
      <link name='front_right_wheel_link'>
        <pose relative_to='front_right_wheel_joint'>0 0 0 0 -0 0</pose>
        <inertial>
          <pose>0 0 0 0 -0 0</pose>
          <mass>2.6</mass>
          <inertia>
            <ixx>0.00138624</ixx>
            <ixy>0</ixy>
            <ixz>0</ixz>
            <iyy>0.00138624</iyy>
            <iyz>0</iyz>
            <izz>0.00138624</izz>
          </inertia>
        </inertial>
        <collision name='front_right_wheel_link_collision'>
          <pose>0 0 0 1.5708 -0 0</pose>
          <geometry>
            <cylinder>
              <length>0.056</length>
              <radius>0.076</radius>
            </cylinder>
          </geometry>
          <surface>
            <contact>
              <ode/>
            </contact>
            <friction>
              <ode>
                <mu>0.01</mu>
                <mu2>0.01</mu2>
              </ode>
              <torsional>
                <ode/>
              </torsional>
            </friction>
            <bounce/>
          </surface>
          <max_contacts>10</max_contacts>
        </collision>
        <visual name='front_right_wheel_link_visual'>
          <pose>0 0 0 1.5708 -0 0</pose>
          <geometry>
            <cylinder>
              <length>0.056</length>
              <radius>0.076</radius>
            </cylinder>
          </geometry>
          <material>
            <ambient>0.1764 0.4588 0.8509 1</ambient>
            <diffuse>0.1764 0.4588 0.8509 1</diffuse>
            <specular>0.1764 0.4588 0.8509 1</specular>
            <emissive>0 0 0 0</emissive>
          </material>
        </visual>
        <self_collide>0</self_collide>
        <enable_wind>0</enable_wind>
        <kinematic>0</kinematic>
      </link>
      <joint name='rear_left_wheel_joint' type='revolute'>
        <pose relative_to='base_link'>-0.15 0.183 0.076 0 -0 0</pose>
        <parent>base_link</parent>
        <child>rear_left_wheel_link</child>
        <axis>
          <xyz>0 1 0</xyz>
          <limit>
            <lower>-1e+16</lower>
            <upper>1e+16</upper>
          </limit>
          <dynamics>
            <spring_reference>0</spring_reference>
            <spring_stiffness>0</spring_stiffness>
          </dynamics>
        </axis>
      </joint>
      <link name='rear_left_wheel_link'>
        <pose relative_to='rear_left_wheel_joint'>0 0 0 0 -0 0</pose>
        <inertial>
          <pose>0 0 0 0 -0 0</pose>
          <mass>2.6</mass>
          <inertia>
            <ixx>0.00138624</ixx>
            <ixy>0</ixy>
            <ixz>0</ixz>
            <iyy>0.00138624</iyy>
            <iyz>0</iyz>
            <izz>0.00138624</izz>
          </inertia>
        </inertial>
        <collision name='rear_left_wheel_link_collision'>
          <pose>0 0 0 1.5708 -0 0</pose>
          <geometry>
            <cylinder>
              <length>0.056</length>
              <radius>0.076</radius>
            </cylinder>
          </geometry>
          <surface>
            <contact>
              <ode/>
            </contact>
            <friction>
              <ode>
                <mu>0.01</mu>
                <mu2>0.01</mu2>
              </ode>
              <torsional>
                <ode/>
              </torsional>
            </friction>
            <bounce/>
          </surface>
          <max_contacts>10</max_contacts>
        </collision>
        <visual name='rear_left_wheel_link_visual'>
          <pose>0 0 0 1.5708 -0 0</pose>
          <geometry>
            <cylinder>
              <length>0.056</length>
              <radius>0.076</radius>
            </cylinder>
          </geometry>
          <material>
            <ambient>0.1764 0.4588 0.8509 1</ambient>
            <diffuse>0.1764 0.4588 0.8509 1</diffuse>
            <specular>0.1764 0.4588 0.8509 1</specular>
            <emissive>0 0 0 0</emissive>
          </material>
        </visual>
        <self_collide>0</self_collide>
        <enable_wind>0</enable_wind>
        <kinematic>0</kinematic>
      </link>
      <joint name='rear_right_wheel_joint' type='revolute'>
        <pose relative_to='base_link'>-0.15 -0.183 0.076 0 -0 0</pose>
        <parent>base_link</parent>
        <child>rear_right_wheel_link</child>
        <axis>
          <xyz>0 1 0</xyz>
          <limit>
            <lower>-1e+16</lower>
            <upper>1e+16</upper>
          </limit>
          <dynamics>
            <spring_reference>0</spring_reference>
            <spring_stiffness>0</spring_stiffness>
          </dynamics>
        </axis>
      </joint>
      <link name='rear_right_wheel_link'>
        <pose relative_to='rear_right_wheel_joint'>0 0 0 0 -0 0</pose>
        <inertial>
          <pose>0 0 0 0 -0 0</pose>
          <mass>2.6</mass>
          <inertia>
            <ixx>0.00138624</ixx>
            <ixy>0</ixy>
            <ixz>0</ixz>
            <iyy>0.00138624</iyy>
            <iyz>0</iyz>
            <izz>0.00138624</izz>
          </inertia>
        </inertial>
        <collision name='rear_right_wheel_link_collision'>
          <pose>0 0 0 1.5708 -0 0</pose>
          <geometry>
            <cylinder>
              <length>0.056</length>
              <radius>0.076</radius>
            </cylinder>
          </geometry>
          <surface>
            <contact>
              <ode/>
            </contact>
            <friction>
              <ode>
                <mu>0.01</mu>
                <mu2>0.01</mu2>
              </ode>
              <torsional>
                <ode/>
              </torsional>
            </friction>
            <bounce/>
          </surface>
          <max_contacts>10</max_contacts>
        </collision>
        <visual name='rear_right_wheel_link_visual'>
          <pose>0 0 0 1.5708 -0 0</pose>
          <geometry>
            <cylinder>
              <length>0.056</length>
              <radius>0.076</radius>
            </cylinder>
          </geometry>
          <material>
            <ambient>0.1764 0.4588 0.8509 1</ambient>
            <diffuse>0.1764 0.4588 0.8509 1</diffuse>
            <specular>0.1764 0.4588 0.8509 1</specular>
            <emissive>0 0 0 0</emissive>
          </material>
        </visual>
        <self_collide>0</self_collide>
        <enable_wind>0</enable_wind>
        <kinematic>0</kinematic>
      </link>

    <plugin name='object_controller' filename='libgazebo_ros_planar_move.so'>

      <ros>
        <!-- <namespace>multigo</namespace> -->
      </ros>

      <num_wheel_pairs>2</num_wheel_pairs>
      <left_joint>front_left_wheel_joint</left_joint>
      <right_joint>front_right_wheel_joint</right_joint>
      <left_joint>rear_left_wheel_joint</left_joint>
      <right_joint>rear_right_wheel_joint</right_joint>

      <update_rate>30</update_rate>

      <!-- wheels -->
      <!-- <left_joint>front_left_wheel_joint</left_joint>
      <right_joint>front_right_wheel_joint</right_joint> -->

      <!-- kinematics -->
      <wheel_separation>0.366</wheel_separation>
      <wheel_diameter>0.152</wheel_diameter>

      <!-- limits -->
      <max_wheel_torque>20</max_wheel_torque>
      <max_wheel_acceleration>1.0</max_wheel_acceleration>

      <command_topic>cmd_vel</command_topic>

      <!-- output -->
      <publish_odom>true</publish_odom>
      <publish_odom_tf>true</publish_odom_tf>
      <publish_wheel_tf>false</publish_wheel_tf>

      <odometry_topic>odom</odometry_topic>
      <odometry_frame>odom</odometry_frame>
      <robot_base_frame>base_footprint</robot_base_frame>

    </plugin>


    <plugin name="multigo_joint_state" filename="libgazebo_ros_joint_state_publisher.so">
      <ros>
        <!-- <namespace>multigo</namespace> -->
        <remapping>~/out:=joint_states</remapping>
      </ros>
      <update_rate>30</update_rate>
      <joint_name>front_left_wheel_joint</joint_name>
      <joint_name>front_right_wheel_joint</joint_name>
      <joint_name>rear_left_wheel_joint</joint_name>
      <joint_name>rear_right_wheel_joint</joint_name>
      <joint_name>camera_front_joint</joint_name>
      <joint_name>camera_joint</joint_name>

    </plugin>    

  </model>
</sdf>
