<?xml version="1.0" ?>
<robot name="multigo" xmlns:xacro="http://ros.org/wiki/xacro">

  <!-- Init colour -->
  <material name="black">
      <color rgba="0.0 0.0 0.0 1.0"/>
  </material>

  <material name="dark">
    <color rgba="0.3 0.3 0.3 1.0"/>
  </material>

  <material name="light_black">
    <color rgba="0.4 0.4 0.4 1.0"/>
  </material>

  <material name="blue">
    <color rgba="0.0 0.0 0.8 1.0"/>
  </material>

  <material name="green">
    <color rgba="0.0 0.8 0.0 1.0"/>
  </material>

  <material name="grey">
    <color rgba="0.5 0.5 0.5 1.0"/>
  </material>

  <material name="orange">
    <color rgba="1.0 0.4235 0.0392 1.0"/>
  </material>

  <material name="brown">
    <color rgba="0.8706 0.8118 0.7647 1.0"/>
  </material>

  <material name="red">
    <color rgba="0.8 0.0 0.0 1.0"/>
  </material>

  <material name="white">
    <color rgba="1.0 1.0 1.0 1.0"/>
  </material>

  <!-- Base Footprint -->
  <link name="base_footprint"/>

  <joint name="base_joint" type="fixed">
    <parent link="base_footprint"/>
    <child link="base_link" />
    <origin xyz="0 0 0.010" rpy="0 0 0"/>
  </joint>

  <!-- Base Link -->
  <link name="base_link">
    <inertial>
      <pose>0.000602 0 0.476823 0 -0 0</pose>
      <mass>50.435</mass>
      <inertia>
        <ixx>3.02781</ixx>
        <ixy>0</ixy>
        <ixz>-0.012125</ixz>
        <iyy>3.43197</iyy>
        <iyz>0</iyz>
        <izz>0.968001</izz>
      </inertia>
    </inertial>

    <collision name="base_collision">
      <pose>0.15 0 0.002 -0.0 -0.0 1.57</pose>
      <geometry>
        <mesh>
          <uri>model://multigo/meshes/multigo.stl</uri>
          <scale>0.001 0.001 0.001</scale>
        </mesh>
      </geometry>
    </collision>

    <visual name="base_visual">
      <pose>0.15 0 0.002 -0.0 -0.0 1.57</pose>
      <geometry>
        <mesh>
          <uri>model://multigo/meshes/multigo.stl</uri>
          <scale>0.001 0.001 0.001</scale>
        </mesh>
      </geometry>
      <material>
        <ambient>0.8392 0.6314 0 1</ambient>
        <diffuse>0.8392 0.6314 0 1</diffuse>
        <specular>0.99 0.99 0.99 1</specular>
        <emissive>0 0 0 0</emissive>
      </material>
    </visual>
  </link>

  <!-- Odometry Link -->
  <link name="odom"/>

  <!-- Fixed Joint from odom to base_footprint -->
  <joint name="odom_to_base" type="fixed">
    <parent link="odom"/>
    <child link="base_footprint"/>
    <origin xyz="0 0 0" rpy="0 0 0"/>
  </joint>


  <!-- Front Left Wheel -->
  <joint name="front_left_wheel_joint" type="revolute">
    <parent link="base_link"/>
    <child link="front_left_wheel_link"/>
    <origin xyz="0.15 0.183 0.076" rpy="0 0 0"/>
    <axis xyz="0 1 0"/>
    <limit lower="-1e+16" upper="1e+16" effort="100" velocity="100"/>
    <dynamics damping="0.0" friction="0.0"/>
  </joint>

  <link name="front_left_wheel_link">
    <visual>
      <origin xyz="0 0 0" rpy="1.5708 0 0"/>
      <geometry>
        <cylinder length="0.056" radius="0.076"/>
      </geometry>
      <material name="dark"/>
    </visual>

    <collision>
      <origin xyz="0 0 0" rpy="1.5708 0 0"/>
      <geometry>
        <cylinder length="0.056" radius="0.076"/>
      </geometry>
    </collision>

    <inertial>
      <origin xyz="0 0 0" rpy="0 0 0"/>
      <mass value="0.6"/>
      <inertia ixx="0.00138624" ixy="0" ixz="0" iyy="0.00138624" iyz="0" izz="0.00138624"/>
    </inertial>
  </link>

  <!-- Front Right Wheel -->
  <joint name="front_right_wheel_joint" type="revolute">
    <parent link="base_link"/>
    <child link="front_right_wheel_link"/>
    <origin xyz="0.15 -0.183 0.076" rpy="0 0 0"/>
    <axis xyz="0 1 0"/>
    <limit lower="-1e+16" upper="1e+16" effort="100" velocity="100"/>
    <dynamics damping="0.0" friction="0.0"/>
  </joint>

  <link name="front_right_wheel_link">
    <visual>
      <origin xyz="0 0 0" rpy="1.5708 0 0"/>
      <geometry>
        <cylinder length="0.056" radius="0.076"/>
      </geometry>
      <material name="dark"/>
    </visual>

    <collision>
      <origin xyz="0 0 0" rpy="1.5708 0 0"/>
      <geometry>
        <cylinder length="0.056" radius="0.076"/>
      </geometry>
    </collision>

    <inertial>
      <origin xyz="0 0 0" rpy="0 0 0"/>
      <mass value="0.6"/>
      <inertia ixx="0.00138624" ixy="0" ixz="0" iyy="0.00138624" iyz="0" izz="0.00138624"/>
    </inertial>
  </link>

  <!-- Rear Left Wheel -->
  <joint name="rear_left_wheel_joint" type="revolute">
    <parent link="base_link"/>
    <child link="rear_left_wheel_link"/>
    <origin xyz="-0.15 0.183 0.076" rpy="0 0 0"/>
    <axis xyz="0 1 0"/>
    <limit lower="-1e+16" upper="1e+16" effort="100" velocity="100"/>
    <dynamics damping="0.0" friction="0.0"/>
  </joint>

  <link name="rear_left_wheel_link">
    <visual>
      <origin xyz="0 0 0" rpy="1.5708 0 0"/>
      <geometry>
        <cylinder length="0.056" radius="0.076"/>
      </geometry>
      <material name="dark"/>
    </visual>

    <collision>
      <origin xyz="0 0 0" rpy="1.5708 0 0"/>
      <geometry>
        <cylinder length="0.056" radius="0.076"/>
      </geometry>
    </collision>

    <inertial>
      <origin xyz="0 0 0" rpy="0 0 0"/>
      <mass value="0.6"/>
      <inertia ixx="0.00138624" ixy="0" ixz="0" iyy="0.00138624" iyz="0" izz="0.00138624"/>
    </inertial>
  </link>

  <!-- Rear Right Wheel -->
  <joint name="rear_right_wheel_joint" type="revolute">
    <parent link="base_link"/>
    <child link="rear_right_wheel_link"/>
    <origin xyz="-0.15 -0.183 0.076" rpy="0 0 0"/>
    <axis xyz="0 1 0"/>
    <limit lower="-1e+16" upper="1e+16" effort="100" velocity="100"/>
    <dynamics damping="0.0" friction="0.0"/>
  </joint>

  <link name="rear_right_wheel_link">
    <visual>
      <origin xyz="0 0 0" rpy="1.5708 0 0"/>
      <geometry>
        <cylinder length="0.056" radius="0.076"/>
      </geometry>
      <material name="dark"/>
    </visual>

    <collision>
      <origin xyz="0 0 0" rpy="1.5708 0 0"/>
      <geometry>
        <cylinder length="0.056" radius="0.076"/>
      </geometry>
    </collision>

    <inertial>
      <origin xyz="0 0 0" rpy="0 0 0"/>
      <mass value="0.6"/>
      <inertia ixx="0.00138624" ixy="0" ixz="0" iyy="0.00138624" iyz="0" izz="0.00138624"/>
    </inertial>
  </link>

  <!-- LIDAR Joint -->
  <joint name="scan_joint" type="fixed">
    <parent link="base_link"/>
    <child link="base_scan"/>
    <origin xyz="0.21 0 0.5" rpy="0 0 0"/>
  </joint>

  <link name="base_scan">
    <visual>
      <origin xyz="0 0 0" rpy="0 0 0"/>
      <geometry>
        <cylinder length="0.02" radius="0.2"/>
      </geometry>
      <material name="green"/>
    </visual>

    <collision>
      <origin xyz="0 0 0" rpy="0 0 0"/>
      <geometry>
        <cylinder length="0.02" radius="0.2"/>
      </geometry>
    </collision>

    <inertial>
      <origin xyz="0 0 0" rpy="0 0 0"/>
      <mass value="0.5"/>
      <inertia ixx="0.005" ixy="0" ixz="0" iyy="0.005" iyz="0" izz="0.005"/>
    </inertial>
  </link>

  <joint name="imu_joint" type="fixed">
    <parent link="base_link"/>
    <child link="imu_link"/>
    <origin xyz="0.0 0 0.5" rpy="0 0 0"/>
  </joint>

  <link name="imu_link">
    <visual>
      <origin xyz="0 0 0" rpy="0 0 0"/>
      <geometry>
        <cylinder length="0.02" radius="0.2"/>
      </geometry>
      <material name="green"/>
    </visual>

    <collision>
      <origin xyz="0 0 0" rpy="0 0 0"/>
      <geometry>
        <cylinder length="0.02" radius="0.2"/>
      </geometry>
    </collision>

    <inertial>
      <origin xyz="0 0 0" rpy="0 0 0"/>
      <mass value="0.5"/>
      <inertia ixx="0.005" ixy="0" ixz="0" iyy="0.005" iyz="0" izz="0.005"/>
    </inertial>
  </link>

  <!-- Camera Joint -->
  <joint name="camera_joint" type="fixed">
    <parent link="base_link"/>
    <child link="camera_link"/>
    <origin xyz="0.26 0.0 0.30" rpy="0 0 0"/>
  </joint>

  <link name="camera_link">
    <visual>
      <origin xyz="0 0 0" rpy="0 0 0"/>
      <geometry>
        <box size="0.1 0.1 0.1"/>
      </geometry>
      <material name="white"/>
    </visual>

    <collision>
      <origin xyz="0 0 0" rpy="0 0 0"/>
      <geometry>
        <box size="0.1 0.1 0.1"/>
      </geometry>
    </collision>

    <inertial>
      <origin xyz="0 0 0" rpy="0 0 0"/>
      <mass value="0.5"/>
      <inertia ixx="0.005" ixy="0" ixz="0" iyy="0.005" iyz="0" izz="0.005"/>
    </inertial>
  </link>

   <!-- Front Left Camera -->
  <joint name="camera_front_left_joint" type="fixed">
    <parent link="camera_link"/>
    <child link="camera_front_left_frame"/>
    <origin xyz="-0.082 0.178 0.0" rpy="0 0 0"/>
  </joint>

  <link name="camera_front_left_frame">
    <visual>
      <origin xyz="0 0 0" rpy="0 0 0"/>
      <geometry>
        <box size="0.1 0.1 0.1"/>
      </geometry>
      <material name="white"/>
    </visual>

    <collision>
      <origin xyz="0 0 0" rpy="0 0 0"/>
      <geometry>
        <box size="0.1 0.1 0.1"/>
      </geometry>
    </collision>

    <inertial>
      <origin xyz="0 0 0" rpy="0 0 0"/>
      <mass value="0.5"/>
      <inertia ixx="0.005" ixy="0" ixz="0" iyy="0.005" iyz="0" izz="0.005"/>
    </inertial>
  </link>

  <!-- Front Right Camera -->
  <joint name="camera_front_right_joint" type="fixed">
    <parent link="camera_link"/>
    <child link="camera_front_right_frame"/>
    <origin xyz="-0.082 -0.178 0.0" rpy="0 0 0"/>
  </joint>

  <link name="camera_front_right_frame">
    <visual>
      <origin xyz="0 0 0" rpy="0 0 0"/>
      <geometry>
        <box size="0.1 0.1 0.1"/>
      </geometry>
      <material name="white"/>
    </visual>

    <collision>
      <origin xyz="0 0 0" rpy="0 0 0"/>
      <geometry>
        <box size="0.1 0.1 0.1"/>
      </geometry>
    </collision>

    <inertial>
      <origin xyz="0 0 0" rpy="0 0 0"/>
      <mass value="0.5"/>
      <inertia ixx="0.005" ixy="0" ixz="0" iyy="0.005" iyz="0" izz="0.005"/>
    </inertial>
  </link>

</robot>
